Workbook

Sheet irish_model_summary_rebuilt
A1: task_name | B1: model_name | C1: task_model | D1: n_samples | E1: n_speakers | F1: n_classes | G1: class_counts | H1: label_classes | I1: accuracy_mean | J1: accuracy_std | K1: balanced_accuracy_mean | L1: macro_f1_mean | M1: Baseline | N1: relative_improvement
A2: dail_only_province | B2: knn_k1 | C2: =_xlfn.CONCAT(Table1[[#This Row],[task_name]]," - ",Table1[[#This Row],[model_name]]) -> dail_only_province - knn_k1 | D2: 1226 | E2: 189 | F2: 4 | G2: {"Leinster": 481, "Munster": 347, "Connacht": 233, "Ulster": 165} | H2: ["Connacht", "Leinster", "Munster", "Ulster"] | I2: 0.3116580745721339 | J2: 0.030508867940240252 | K2: 0.26418717623214105 | L2: 0.25284943007307914 | M2: =1/Table1[[#This Row],[n_classes]] -> 0.25 | N2: =(Table1[[#This Row],[balanced_accuracy_mean]]-Table1[[#This Row],[Baseline]])/Table1[[#This Row],[Baseline]] -> 0.056748705
A3: dail_only_province | B3: knn_k11 | C3: =_xlfn.CONCAT(Table1[[#This Row],[task_name]]," - ",Table1[[#This Row],[model_name]]) -> dail_only_province - knn_k11 | D3: 1226 | E3: 189 | F3: 4 | G3: {"Leinster": 481, "Munster": 347, "Connacht": 233, "Ulster": 165} | H3: ["Connacht", "Leinster", "Munster", "Ulster"] | I3: 0.32645344285260225 | J3: 0.046151997454951216 | K3: 0.27008932574240363 | L3: 0.24835835713765028 | M3: =1/Table1[[#This Row],[n_classes]] -> 0.25 | N3: =(Table1[[#This Row],[balanced_accuracy_mean]]-Table1[[#This Row],[Baseline]])/Table1[[#This Row],[Baseline]] -> 0.080357303
A4: dail_only_province | B4: knn_k3 | C4: =_xlfn.CONCAT(Table1[[#This Row],[task_name]]," - ",Table1[[#This Row],[model_name]]) -> dail_only_province - knn_k3 | D4: 1226 | E4: 189 | F4: 4 | G4: {"Leinster": 481, "Munster": 347, "Connacht": 233, "Ulster": 165} | H4: ["Connacht", "Leinster", "Munster", "Ulster"] | I4: 0.3030958931692115 | J4: 0.024456747 | K4: 0.2636679032820017 | L4: 0.2490282190677308 | M4: =1/Table1[[#This Row],[n_classes]] -> 0.25 | N4: =(Table1[[#This Row],[balanced_accuracy_mean]]-Table1[[#This Row],[Baseline]])/Table1[[#This Row],[Baseline]] -> 0.054671613
A5: dail_only_province | B5: knn_k5 | C5: =_xlfn.CONCAT(Table1[[#This Row],[task_name]]," - ",Table1[[#This Row],[model_name]]) -> dail_only_province - knn_k5 | D5: 1226 | E5: 189 | F5: 4 | G5: {"Leinster": 481, "Munster": 347, "Connacht": 233, "Ulster": 165} | H5: ["Connacht", "Leinster", "Munster", "Ulster"] | I5: 0.31846378182223833 | J5: 0.039592596 | K5: 0.2653770321509325 | L5: 0.2477735585404667 | M5: =1/Table1[[#This Row],[n_classes]] -> 0.25 | N5: =(Table1[[#This Row],[balanced_accuracy_mean]]-Table1[[#This Row],[Baseline]])/Table1[[#This Row],[Baseline]] -> 0.061508129
A6: dail_only_province | B6: knn_k7 | C6: =_xlfn.CONCAT(Table1[[#This Row],[task_name]]," - ",Table1[[#This Row],[model_name]]) -> dail_only_province - knn_k7 | D6: 1226 | E6: 189 | F6: 4 | G6: {"Leinster": 481, "Munster": 347, "Connacht": 233, "Ulster": 165} | H6: ["Connacht", "Leinster", "Munster", "Ulster"] | I6: 0.32799296585510895 | J6: 0.025132097 | K6: 0.26357770750863263 | L6: 0.24536388535089299 | M6: =1/Table1[[#This Row],[n_classes]] -> 0.25 | N6: =(Table1[[#This Row],[balanced_accuracy_mean]]-Table1[[#This Row],[Baseline]])/Table1[[#This Row],[Baseline]] -> 0.05431083
A7: dail_only_province | B7: logreg | C7: =_xlfn.CONCAT(Table1[[#This Row],[task_name]]," - ",Table1[[#This Row],[model_name]]) -> dail_only_province - logreg | D7: 1226 | E7: 189 | F7: 4 | G7: {"Leinster": 481, "Munster": 347, "Connacht": 233, "Ulster": 165} | H7: ["Connacht", "Leinster", "Munster", "Ulster"] | I7: 0.3454489721210622 | J7: 0.045557658 | K7: 0.2721088672581671 | L7: 0.2539634476578346 | M7: =1/Table1[[#This Row],[n_classes]] -> 0.25 | N7: =(Table1[[#This Row],[balanced_accuracy_mean]]-Table1[[#This Row],[Baseline]])/Table1[[#This Row],[Baseline]] -> 0.088435469
A8: dail_only_province | B8: logreg_weighted | C8: =_xlfn.CONCAT(Table1[[#This Row],[task_name]]," - ",Table1[[#This Row],[model_name]]) -> dail_only_province - logreg_weighted | D8: 1226 | E8: 189 | F8: 4 | G8: {"Leinster": 481, "Munster": 347, "Connacht": 233, "Ulster": 165} | H8: ["Connacht", "Leinster", "Munster", "Ulster"] | I8: 0.29943846 | J8: 0.0069414524 | K8: 0.27188960719951955 | L8: 0.2562142555873223 | M8: =1/Table1[[#This Row],[n_classes]] -> 0.25 | N8: =(Table1[[#This Row],[balanced_accuracy_mean]]-Table1[[#This Row],[Baseline]])/Table1[[#This Row],[Baseline]] -> 0.087558429
A9: dail_only_province | B9: nb | C9: =_xlfn.CONCAT(Table1[[#This Row],[task_name]]," - ",Table1[[#This Row],[model_name]]) -> dail_only_province - nb | D9: 1226 | E9: 189 | F9: 4 | G9: {"Leinster": 481, "Munster": 347, "Connacht": 233, "Ulster": 165} | H9: ["Connacht", "Leinster", "Munster", "Ulster"] | I9: 0.29623350566272627 | J9: 0.033466667915344854 | K9: 0.24096703872637568 | L9: 0.23062354425393078 | M9: =1/Table1[[#This Row],[n_classes]] -> 0.25 | N9: =(Table1[[#This Row],[balanced_accuracy_mean]]-Table1[[#This Row],[Baseline]])/Table1[[#This Row],[Baseline]] -> -0.036131845
A10: dail_only_province | B10: rf | C10: =_xlfn.CONCAT(Table1[[#This Row],[task_name]]," - ",Table1[[#This Row],[model_name]]) -> dail_only_province - rf | D10: 1226 | E10: 189 | F10: 4 | G10: {"Leinster": 481, "Munster": 347, "Connacht": 233, "Ulster": 165} | H10: ["Connacht", "Leinster", "Munster", "Ulster"] | I10: 0.33841970809797667 | J10: 0.051191308 | K10: 0.24748213816978462 | L10: 0.21378579755165247 | M10: =1/Table1[[#This Row],[n_classes]] -> 0.25 | N10: =(Table1[[#This Row],[balanced_accuracy_mean]]-Table1[[#This Row],[Baseline]])/Table1[[#This Row],[Baseline]] -> -0.010071447
A11: dail_only_province | B11: svm_linear | C11: =_xlfn.CONCAT(Table1[[#This Row],[task_name]]," - ",Table1[[#This Row],[model_name]]) -> dail_only_province - svm_linear | D11: 1226 | E11: 189 | F11: 4 | G11: {"Leinster": 481, "Munster": 347, "Connacht": 233, "Ulster": 165} | H11: ["Connacht", "Leinster", "Munster", "Ulster"] | I11: 0.33756797487448437 | J11: 0.066309254 | K11: 0.2612561010787591 | L11: 0.2369943969119785 | M11: =1/Table1[[#This Row],[n_classes]] -> 0.25 | N11: =(Table1[[#This Row],[balanced_accuracy_mean]]-Table1[[#This Row],[Baseline]])/Table1[[#This Row],[Baseline]] -> 0.045024404
A12: dail_only_province | B12: svm_rbf | C12: =_xlfn.CONCAT(Table1[[#This Row],[task_name]]," - ",Table1[[#This Row],[model_name]]) -> dail_only_province - svm_rbf | D12: 1226 | E12: 189 | F12: 4 | G12: {"Leinster": 481, "Munster": 347, "Connacht": 233, "Ulster": 165} | H12: ["Connacht", "Leinster", "Munster", "Ulster"] | I12: 0.3805883126526338 | J12: 0.059185826374159076 | K12: 0.2468638129049962 | L12: 0.16633684373164648 | M12: =1/Table1[[#This Row],[n_classes]] -> 0.25 | N12: =(Table1[[#This Row],[balanced_accuracy_mean]]-Table1[[#This Row],[Baseline]])/Table1[[#This Row],[Baseline]] -> -0.012544748
A13: dail_vs_ni | B13: knn_k1 | C13: =_xlfn.CONCAT(Table1[[#This Row],[task_name]]," - ",Table1[[#This Row],[model_name]]) -> dail_vs_ni - knn_k1 | D13: 1674 | E13: 212 | F13: 2 | G13: {"DAIL": 1282, "NI": 392} | H13: ["DAIL", "NI"] | I13: 0.8100924385144695 | J13: 0.025615938721389418 | K13: 0.66043167 | L13: 0.6827946408211808 | M13: =1/Table1[[#This Row],[n_classes]] -> 0.5 | N13: =(Table1[[#This Row],[balanced_accuracy_mean]]-Table1[[#This Row],[Baseline]])/Table1[[#This Row],[Baseline]] -> 0.32086334
A14: dail_vs_ni | B14: knn_k11 | C14: =_xlfn.CONCAT(Table1[[#This Row],[task_name]]," - ",Table1[[#This Row],[model_name]]) -> dail_vs_ni - knn_k11 | D14: 1674 | E14: 212 | F14: 2 | G14: {"DAIL": 1282, "NI": 392} | H14: ["DAIL", "NI"] | I14: 0.8118570200867434 | J14: 0.037374725 | K14: 0.6569374047168719 | L14: 0.6820807389339831 | M14: =1/Table1[[#This Row],[n_classes]] -> 0.5 | N14: =(Table1[[#This Row],[balanced_accuracy_mean]]-Table1[[#This Row],[Baseline]])/Table1[[#This Row],[Baseline]] -> 0.31387481
A15: dail_vs_ni | B15: knn_k3 | C15: =_xlfn.CONCAT(Table1[[#This Row],[task_name]]," - ",Table1[[#This Row],[model_name]]) -> dail_vs_ni - knn_k3 | D15: 1674 | E15: 212 | F15: 2 | G15: {"DAIL": 1282, "NI": 392} | H15: ["DAIL", "NI"] | I15: 0.8190537711801946 | J15: 0.033383343 | K15: 0.6688377080521959 | L15: 0.6953187672791197 | M15: =1/Table1[[#This Row],[n_classes]] -> 0.5 | N15: =(Table1[[#This Row],[balanced_accuracy_mean]]-Table1[[#This Row],[Baseline]])/Table1[[#This Row],[Baseline]] -> 0.33767542
A16: dail_vs_ni | B16: knn_k5 | C16: =_xlfn.CONCAT(Table1[[#This Row],[task_name]]," - ",Table1[[#This Row],[model_name]]) -> dail_vs_ni - knn_k5 | D16: 1674 | E16: 212 | F16: 2 | G16: {"DAIL": 1282, "NI": 392} | H16: ["DAIL", "NI"] | I16: 0.8220173411377223 | J16: 0.029024269 | K16: 0.6709507312009888 | L16: 0.6977747959231456 | M16: =1/Table1[[#This Row],[n_classes]] -> 0.5 | N16: =(Table1[[#This Row],[balanced_accuracy_mean]]-Table1[[#This Row],[Baseline]])/Table1[[#This Row],[Baseline]] -> 0.34190146
A17: dail_vs_ni | B17: knn_k7 | C17: =_xlfn.CONCAT(Table1[[#This Row],[task_name]]," - ",Table1[[#This Row],[model_name]]) -> dail_vs_ni - knn_k7 | D17: 1674 | E17: 212 | F17: 2 | G17: {"DAIL": 1282, "NI": 392} | H17: ["DAIL", "NI"] | I17: 0.81244684 | J17: 0.039615866001476346 | K17: 0.6583880407841521 | L17: 0.6834956501525076 | M17: =1/Table1[[#This Row],[n_classes]] -> 0.5 | N17: =(Table1[[#This Row],[balanced_accuracy_mean]]-Table1[[#This Row],[Baseline]])/Table1[[#This Row],[Baseline]] -> 0.31677608
A18: dail_vs_ni | B18: logreg | C18: =_xlfn.CONCAT(Table1[[#This Row],[task_name]]," - ",Table1[[#This Row],[model_name]]) -> dail_vs_ni - logreg | D18: 1674 | E18: 212 | F18: 2 | G18: {"DAIL": 1282, "NI": 392} | H18: ["DAIL", "NI"] | I18: 0.8305310691552847 | J18: 0.050155079 | K18: 0.7237458136120851 | L18: 0.73700339 | M18: =1/Table1[[#This Row],[n_classes]] -> 0.5 | N18: =(Table1[[#This Row],[balanced_accuracy_mean]]-Table1[[#This Row],[Baseline]])/Table1[[#This Row],[Baseline]] -> 0.44749163
A19: dail_vs_ni | B19: logreg_weighted | C19: =_xlfn.CONCAT(Table1[[#This Row],[task_name]]," - ",Table1[[#This Row],[model_name]]) -> dail_vs_ni - logreg_weighted | D19: 1674 | E19: 212 | F19: 2 | G19: {"DAIL": 1282, "NI": 392} | H19: ["DAIL", "NI"] | I19: 0.8131536875726976 | J19: 0.068072264 | K19: 0.7654502943119464 | L19: 0.7492227863873708 | M19: =1/Table1[[#This Row],[n_classes]] -> 0.5 | N19: =(Table1[[#This Row],[balanced_accuracy_mean]]-Table1[[#This Row],[Baseline]])/Table1[[#This Row],[Baseline]] -> 0.53090059
A20: dail_vs_ni | B20: nb | C20: =_xlfn.CONCAT(Table1[[#This Row],[task_name]]," - ",Table1[[#This Row],[model_name]]) -> dail_vs_ni - nb | D20: 1674 | E20: 212 | F20: 2 | G20: {"DAIL": 1282, "NI": 392} | H20: ["DAIL", "NI"] | I20: 0.8667303935227476 | J20: 0.046149513770467936 | K20: 0.7874226790703526 | L20: 0.7955000313574867 | M20: =1/Table1[[#This Row],[n_classes]] -> 0.5 | N20: =(Table1[[#This Row],[balanced_accuracy_mean]]-Table1[[#This Row],[Baseline]])/Table1[[#This Row],[Baseline]] -> 0.57484536
A21: dail_vs_ni | B21: rf | C21: =_xlfn.CONCAT(Table1[[#This Row],[task_name]]," - ",Table1[[#This Row],[model_name]]) -> dail_vs_ni - rf | D21: 1674 | E21: 212 | F21: 2 | G21: {"DAIL": 1282, "NI": 392} | H21: ["DAIL", "NI"] | I21: 0.84590784 | J21: 0.032688588 | K21: 0.7170707008030599 | L21: 0.7441865723745854 | M21: =1/Table1[[#This Row],[n_classes]] -> 0.5 | N21: =(Table1[[#This Row],[balanced_accuracy_mean]]-Table1[[#This Row],[Baseline]])/Table1[[#This Row],[Baseline]] -> 0.4341414
A22: dail_vs_ni | B22: svm_linear | C22: =_xlfn.CONCAT(Table1[[#This Row],[task_name]]," - ",Table1[[#This Row],[model_name]]) -> dail_vs_ni - svm_linear | D22: 1674 | E22: 212 | F22: 2 | G22: {"DAIL": 1282, "NI": 392} | H22: ["DAIL", "NI"] | I22: 0.8400324917841766 | J22: 0.047685447 | K22: 0.73857219 | L22: 0.7526674731696748 | M22: =1/Table1[[#This Row],[n_classes]] -> 0.5 | N22: =(Table1[[#This Row],[balanced_accuracy_mean]]-Table1[[#This Row],[Baseline]])/Table1[[#This Row],[Baseline]] -> 0.47714438
A23: dail_vs_ni | B23: svm_rbf | C23: =_xlfn.CONCAT(Table1[[#This Row],[task_name]]," - ",Table1[[#This Row],[model_name]]) -> dail_vs_ni - svm_rbf | D23: 1674 | E23: 212 | F23: 2 | G23: {"DAIL": 1282, "NI": 392} | H23: ["DAIL", "NI"] | I23: 0.82087183 | J23: 0.021449635113381847 | K23: 0.6583123547914729 | L23: 0.68346967 | M23: =1/Table1[[#This Row],[n_classes]] -> 0.5 | N23: =(Table1[[#This Row],[balanced_accuracy_mean]]-Table1[[#This Row],[Baseline]])/Table1[[#This Row],[Baseline]] -> 0.31662471
A24: leinster_vs_rest | B24: knn_k1 | C24: =_xlfn.CONCAT(Table1[[#This Row],[task_name]]," - ",Table1[[#This Row],[model_name]]) -> leinster_vs_rest - knn_k1 | D24: 1618 | E24: 206 | F24: 2 | G24: {"Rest": 1137, "Leinster": 481} | H24: ["Leinster", "Rest"] | I24: 0.5909070060772847 | J24: 0.067893478 | K24: 0.5493421699999124 | L24: 0.5414689612019521 | M24: =1/Table1[[#This Row],[n_classes]] -> 0.5 | N24: =(Table1[[#This Row],[balanced_accuracy_mean]]-Table1[[#This Row],[Baseline]])/Table1[[#This Row],[Baseline]] -> 0.09868434
A25: leinster_vs_rest | B25: knn_k11 | C25: =_xlfn.CONCAT(Table1[[#This Row],[task_name]]," - ",Table1[[#This Row],[model_name]]) -> leinster_vs_rest - knn_k11 | D25: 1618 | E25: 206 | F25: 2 | G25: {"Rest": 1137, "Leinster": 481} | H25: ["Leinster", "Rest"] | I25: 0.6632190498031572 | J25: 0.06951959 | K25: 0.5725921562558014 | L25: 0.57526025 | M25: =1/Table1[[#This Row],[n_classes]] -> 0.5 | N25: =(Table1[[#This Row],[balanced_accuracy_mean]]-Table1[[#This Row],[Baseline]])/Table1[[#This Row],[Baseline]] -> 0.14518431
A26: leinster_vs_rest | B26: knn_k3 | C26: =_xlfn.CONCAT(Table1[[#This Row],[task_name]]," - ",Table1[[#This Row],[model_name]]) -> leinster_vs_rest - knn_k3 | D26: 1618 | E26: 206 | F26: 2 | G26: {"Rest": 1137, "Leinster": 481} | H26: ["Leinster", "Rest"] | I26: 0.6162156480525934 | J26: 0.036388736 | K26: 0.5583386940345777 | L26: 0.5539981855702578 | M26: =1/Table1[[#This Row],[n_classes]] -> 0.5 | N26: =(Table1[[#This Row],[balanced_accuracy_mean]]-Table1[[#This Row],[Baseline]])/Table1[[#This Row],[Baseline]] -> 0.11667739
A27: leinster_vs_rest | B27: knn_k5 | C27: =_xlfn.CONCAT(Table1[[#This Row],[task_name]]," - ",Table1[[#This Row],[model_name]]) -> leinster_vs_rest - knn_k5 | D27: 1618 | E27: 206 | F27: 2 | G27: {"Rest": 1137, "Leinster": 481} | H27: ["Leinster", "Rest"] | I27: 0.6323089859725567 | J27: 0.049903740371596055 | K27: 0.56140122 | L27: 0.5602532568056804 | M27: =1/Table1[[#This Row],[n_classes]] -> 0.5 | N27: =(Table1[[#This Row],[balanced_accuracy_mean]]-Table1[[#This Row],[Baseline]])/Table1[[#This Row],[Baseline]] -> 0.12280244
A28: leinster_vs_rest | B28: knn_k7 | C28: =_xlfn.CONCAT(Table1[[#This Row],[task_name]]," - ",Table1[[#This Row],[model_name]]) -> leinster_vs_rest - knn_k7 | D28: 1618 | E28: 206 | F28: 2 | G28: {"Rest": 1137, "Leinster": 481} | H28: ["Leinster", "Rest"] | I28: 0.6539578794480756 | J28: 0.062653224 | K28: 0.5762099996573932 | L28: 0.5770839227877762 | M28: =1/Table1[[#This Row],[n_classes]] -> 0.5 | N28: =(Table1[[#This Row],[balanced_accuracy_mean]]-Table1[[#This Row],[Baseline]])/Table1[[#This Row],[Baseline]] -> 0.15242
A29: leinster_vs_rest | B29: logreg | C29: =_xlfn.CONCAT(Table1[[#This Row],[task_name]]," - ",Table1[[#This Row],[model_name]]) -> leinster_vs_rest - logreg | D29: 1618 | E29: 206 | F29: 2 | G29: {"Rest": 1137, "Leinster": 481} | H29: ["Leinster", "Rest"] | I29: 0.6515040324121852 | J29: 0.15388004764947336 | K29: 0.5583668296240168 | L29: 0.5627621338256843 | M29: =1/Table1[[#This Row],[n_classes]] -> 0.5 | N29: =(Table1[[#This Row],[balanced_accuracy_mean]]-Table1[[#This Row],[Baseline]])/Table1[[#This Row],[Baseline]] -> 0.11673366
A30: leinster_vs_rest | B30: logreg_weighted | C30: =_xlfn.CONCAT(Table1[[#This Row],[task_name]]," - ",Table1[[#This Row],[model_name]]) -> leinster_vs_rest - logreg_weighted | D30: 1618 | E30: 206 | F30: 2 | G30: {"Rest": 1137, "Leinster": 481} | H30: ["Leinster", "Rest"] | I30: 0.6051542254328631 | J30: 0.16454207141563473 | K30: 0.6157772234983663 | L30: 0.5834602710390221 | M30: =1/Table1[[#This Row],[n_classes]] -> 0.5 | N30: =(Table1[[#This Row],[balanced_accuracy_mean]]-Table1[[#This Row],[Baseline]])/Table1[[#This Row],[Baseline]] -> 0.23155445
A31: leinster_vs_rest | B31: nb | C31: =_xlfn.CONCAT(Table1[[#This Row],[task_name]]," - ",Table1[[#This Row],[model_name]]) -> leinster_vs_rest - nb | D31: 1618 | E31: 206 | F31: 2 | G31: {"Rest": 1137, "Leinster": 481} | H31: ["Leinster", "Rest"] | I31: 0.5706264572105646 | J31: 0.1787605805578662 | K31: 0.6002314065085735 | L31: 0.5545449433068046 | M31: =1/Table1[[#This Row],[n_classes]] -> 0.5 | N31: =(Table1[[#This Row],[balanced_accuracy_mean]]-Table1[[#This Row],[Baseline]])/Table1[[#This Row],[Baseline]] -> 0.20046281
A32: leinster_vs_rest | B32: rf | C32: =_xlfn.CONCAT(Table1[[#This Row],[task_name]]," - ",Table1[[#This Row],[model_name]]) -> leinster_vs_rest - rf | D32: 1618 | E32: 206 | F32: 2 | G32: {"Rest": 1137, "Leinster": 481} | H32: ["Leinster", "Rest"] | I32: 0.6508886595573902 | J32: 0.11450756222419754 | K32: 0.5213249965340937 | L32: 0.5128920320899167 | M32: =1/Table1[[#This Row],[n_classes]] -> 0.5 | N32: =(Table1[[#This Row],[balanced_accuracy_mean]]-Table1[[#This Row],[Baseline]])/Table1[[#This Row],[Baseline]] -> 0.042649993
A33: leinster_vs_rest | B33: svm_linear | C33: =_xlfn.CONCAT(Table1[[#This Row],[task_name]]," - ",Table1[[#This Row],[model_name]]) -> leinster_vs_rest - svm_linear | D33: 1618 | E33: 206 | F33: 2 | G33: {"Rest": 1137, "Leinster": 481} | H33: ["Leinster", "Rest"] | I33: 0.6515174100829416 | J33: 0.15499734802692297 | K33: 0.5547913638978458 | L33: 0.5594403019124308 | M33: =1/Table1[[#This Row],[n_classes]] -> 0.5 | N33: =(Table1[[#This Row],[balanced_accuracy_mean]]-Table1[[#This Row],[Baseline]])/Table1[[#This Row],[Baseline]] -> 0.10958273
A34: leinster_vs_rest | B34: svm_rbf | C34: =_xlfn.CONCAT(Table1[[#This Row],[task_name]]," - ",Table1[[#This Row],[model_name]]) -> leinster_vs_rest - svm_rbf | D34: 1618 | E34: 206 | F34: 2 | G34: {"Rest": 1137, "Leinster": 481} | H34: ["Leinster", "Rest"] | I34: 0.7027194893551962 | J34: 0.0012615042 | K34: 0.5 | L34: 0.4127039446783785 | M34: =1/Table1[[#This Row],[n_classes]] -> 0.5 | N34: =(Table1[[#This Row],[balanced_accuracy_mean]]-Table1[[#This Row],[Baseline]])/Table1[[#This Row],[Baseline]] -> 0
A35: province_4way | B35: knn_k1 | C35: =_xlfn.CONCAT(Table1[[#This Row],[task_name]]," - ",Table1[[#This Row],[model_name]]) -> province_4way - knn_k1 | D35: 1618 | E35: 206 | F35: 4 | G35: {"Ulster": 541, "Leinster": 481, "Munster": 347, "Connacht": 249} | H35: ["Connacht", "Leinster", "Munster", "Ulster"] | I35: 0.3544166192791238 | J35: 0.052316427 | K35: 0.3290419712327961 | L35: 0.33019904098857555 | M35: =1/Table1[[#This Row],[n_classes]] -> 0.25 | N35: =(Table1[[#This Row],[balanced_accuracy_mean]]-Table1[[#This Row],[Baseline]])/Table1[[#This Row],[Baseline]] -> 0.31616788
A36: province_4way | B36: knn_k11 | C36: =_xlfn.CONCAT(Table1[[#This Row],[task_name]]," - ",Table1[[#This Row],[model_name]]) -> province_4way - knn_k11 | D36: 1618 | E36: 206 | F36: 4 | G36: {"Ulster": 541, "Leinster": 481, "Munster": 347, "Connacht": 249} | H36: ["Connacht", "Leinster", "Munster", "Ulster"] | I36: 0.39921195450111363 | J36: 0.023840540928101898 | K36: 0.34764287719168896 | L36: 0.3419119703158932 | M36: =1/Table1[[#This Row],[n_classes]] -> 0.25 | N36: =(Table1[[#This Row],[balanced_accuracy_mean]]-Table1[[#This Row],[Baseline]])/Table1[[#This Row],[Baseline]] -> 0.39057151
A37: province_4way | B37: knn_k3 | C37: =_xlfn.CONCAT(Table1[[#This Row],[task_name]]," - ",Table1[[#This Row],[model_name]]) -> province_4way - knn_k3 | D37: 1618 | E37: 206 | F37: 4 | G37: {"Ulster": 541, "Leinster": 481, "Munster": 347, "Connacht": 249} | H37: ["Connacht", "Leinster", "Munster", "Ulster"] | I37: 0.3538881071776767 | J37: 0.043625605 | K37: 0.3310614074810821 | L37: 0.3309177715603238 | M37: =1/Table1[[#This Row],[n_classes]] -> 0.25 | N37: =(Table1[[#This Row],[balanced_accuracy_mean]]-Table1[[#This Row],[Baseline]])/Table1[[#This Row],[Baseline]] -> 0.32424563
A38: province_4way | B38: knn_k5 | C38: =_xlfn.CONCAT(Table1[[#This Row],[task_name]]," - ",Table1[[#This Row],[model_name]]) -> province_4way - knn_k5 | D38: 1618 | E38: 206 | F38: 4 | G38: {"Ulster": 541, "Leinster": 481, "Munster": 347, "Connacht": 249} | H38: ["Connacht", "Leinster", "Munster", "Ulster"] | I38: 0.37189517288526847 | J38: 0.037479867986846535 | K38: 0.33470905479884544 | L38: 0.33386768584012627 | M38: =1/Table1[[#This Row],[n_classes]] -> 0.25 | N38: =(Table1[[#This Row],[balanced_accuracy_mean]]-Table1[[#This Row],[Baseline]])/Table1[[#This Row],[Baseline]] -> 0.33883622
A39: province_4way | B39: knn_k7 | C39: =_xlfn.CONCAT(Table1[[#This Row],[task_name]]," - ",Table1[[#This Row],[model_name]]) -> province_4way - knn_k7 | D39: 1618 | E39: 206 | F39: 4 | G39: {"Ulster": 541, "Leinster": 481, "Munster": 347, "Connacht": 249} | H39: ["Connacht", "Leinster", "Munster", "Ulster"] | I39: 0.39034282819417937 | J39: 0.039111077 | K39: 0.3474254392715335 | L39: 0.3432376848154669 | M39: =1/Table1[[#This Row],[n_classes]] -> 0.25 | N39: =(Table1[[#This Row],[balanced_accuracy_mean]]-Table1[[#This Row],[Baseline]])/Table1[[#This Row],[Baseline]] -> 0.38970176
A40: province_4way | B40: logreg | C40: =_xlfn.CONCAT(Table1[[#This Row],[task_name]]," - ",Table1[[#This Row],[model_name]]) -> province_4way - logreg | D40: 1618 | E40: 206 | F40: 4 | G40: {"Ulster": 541, "Leinster": 481, "Munster": 347, "Connacht": 249} | H40: ["Connacht", "Leinster", "Munster", "Ulster"] | I40: 0.4544309556094329 | J40: 0.056634515 | K40: 0.3938290839759699 | L40: 0.3831794300805013 | M40: =1/Table1[[#This Row],[n_classes]] -> 0.25 | N40: =(Table1[[#This Row],[balanced_accuracy_mean]]-Table1[[#This Row],[Baseline]])/Table1[[#This Row],[Baseline]] -> 0.57531634
...

Sheet Charts
A1: task_name | B1: model_name | C1: task_model | D1: balanced_accuracy_mean | E1: macro_f1_mean
A2: dail_only_province | B2: knn_k1 | C2: dail_only_province - knn_k1 | D2: 0.26418718 | E2: 0.25284943
A3: dail_only_province | B3: knn_k11 | C3: dail_only_province - knn_k11 | D3: 0.27008933 | E3: 0.24835836
A4: dail_only_province | B4: knn_k3 | C4: dail_only_province - knn_k3 | D4: 0.2636679 | E4: 0.24902822
A5: dail_only_province | B5: knn_k5 | C5: dail_only_province - knn_k5 | D5: 0.26537703 | E5: 0.24777356
A6: dail_only_province | B6: knn_k7 | C6: dail_only_province - knn_k7 | D6: 0.26357771 | E6: 0.24536389
A7: dail_only_province | B7: logreg | C7: dail_only_province - logreg | D7: 0.27210887 | E7: 0.25396345
A8: dail_only_province | B8: logreg_weighted | C8: dail_only_province - logreg_weighted | D8: 0.27188961 | E8: 0.25621426
A9: dail_only_province | B9: nb | C9: dail_only_province - nb | D9: 0.24096704 | E9: 0.23062354
A10: dail_only_province | B10: rf | C10: dail_only_province - rf | D10: 0.24748214 | E10: 0.2137858
A11: dail_only_province | B11: svm_linear | C11: dail_only_province - svm_linear | D11: 0.2612561 | E11: 0.2369944
A12: dail_only_province | B12: svm_rbf | C12: dail_only_province - svm_rbf | D12: 0.24686381 | E12: 0.16633684
A13: dail_vs_ni | B13: knn_k1 | C13: dail_vs_ni - knn_k1 | D13: 0.66043167 | E13: 0.68279464
... A67: ulster_vs_rest | B67: svm_rbf | C67: ulster_vs_rest - svm_rbf | D67: 0.69674609 | E67: 0.70886431

Sheet Chart 1 - dail_only_province
A1: task_name | B1: task_name_better | C1: model_name | D1: model_name_better | E1: task_model | F1: balanced_accuracy_mean | G1: macro_f1_mean | H1: signal_flag
A2: =A1 -> task_name | B2: Province Classification (Dáil Speakers Only) | C2: random | D2: Random Baseline | E2: =_xlfn.CONCAT(A2, " - ",C2) -> task_name - random | F2: 0.25 | G2: 0.25 | H2: 1
A3: dail_only_province | B3: Province Classification (Dáil Speakers Only) | C3: nb | D3: Naive Bayes | E3: dail_only_province - nb | F3: 0.24096704 | G3: 0.23062354 | H3: 0
A4: dail_only_province | B4: Province Classification (Dáil Speakers Only) | C4: svm_rbf | D4: SVM (RBF Kernel) | E4: dail_only_province - svm_rbf | F4: 0.24686381 | G4: 0.16633684 | H4: 0
A5: dail_only_province | B5: Province Classification (Dáil Speakers Only) | C5: rf | D5: Random Forest | E5: dail_only_province - rf | F5: 0.24748214 | G5: 0.2137858 | H5: 0
A6: dail_only_province | B6: Province Classification (Dáil Speakers Only) | C6: svm_linear | D6: SVM (Linear) | E6: dail_only_province - svm_linear | F6: 0.2612561 | G6: 0.2369944 | H6: 0
A7: dail_only_province | B7: Province Classification (Dáil Speakers Only) | C7: knn_k7 | D7: k-NN (k=7) | E7: dail_only_province - knn_k07 | F7: 0.26357771 | G7: 0.24536389 | H7: 0
A8: dail_only_province | B8: Province Classification (Dáil Speakers Only) | C8: knn_k3 | D8: k-NN (k=3) | E8: dail_only_province - knn_k03 | F8: 0.2636679 | G8: 0.24902822 | H8: 0
A9: dail_only_province | B9: Province Classification (Dáil Speakers Only) | C9: knn_k1 | D9: k-NN (k=1) | E9: dail_only_province - knn_k01 | F9: 0.26418718 | G9: 0.25284943 | H9: 0
A10: dail_only_province | B10: Province Classification (Dáil Speakers Only) | C10: knn_k5 | D10: k-NN (k=5) | E10: dail_only_province - knn_k05 | F10: 0.26537703 | G10: 0.24777356 | H10: 0
A11: dail_only_province | B11: Province Classification (Dáil Speakers Only) | C11: knn_k11 | D11: k-NN (k=11) | E11: dail_only_province - knn_k011 | F11: 0.27008933 | G11: 0.24835836 | H11: 0
A12: dail_only_province | B12: Province Classification (Dáil Speakers Only) | C12: logreg_weighted | D12: Logistic Regression (Weighted) | E12: dail_only_province - logreg_weighted | F12: 0.27188961 | G12: 0.25621426 | H12: 0
A13: dail_only_province | B13: Province Classification (Dáil Speakers Only) | C13: logreg | D13: Logistic Regression | E13: dail_only_province - logreg | F13: 0.27210887 | G13: 0.25396345 | H13: 0
F14: =AVERAGE(F3:F13) -> 0.26067879 | G14: =AVERAGE(G3:G13) -> 0.23648107

Sheet Chart 1 - province_4way
A1: task_name | B1: task_name_better | C1: model_name | D1: model_name_better | E1: task_model | F1: balanced_accuracy_mean | G1: macro_f1_mean | H1: signal_flag
A2: =A1 -> task_name | B2: Multi-Class Classification: Four Provinces | C2: Random | D2: Random Baseline | E2: =_xlfn.CONCAT(A2, " - ",C2) -> task_name - Random | F2: 0.25 | G2: 0.25 | H2: 1
A3: province_4way | B3: Multi-Class Classification: Four Provinces | C3: knn_k1 | D3: k-NN (k=1) | E3: province_4way - knn_k1 | F3: 0.32904197 | G3: 0.33019904 | H3: 0
A4: province_4way | B4: Multi-Class Classification: Four Provinces | C4: knn_k3 | D4: k-NN (k=3) | E4: province_4way - knn_k3 | F4: 0.33106141 | G4: 0.33091777 | H4: 0
A5: province_4way | B5: Multi-Class Classification: Four Provinces | C5: knn_k5 | D5: k-NN (k=5) | E5: province_4way - knn_k5 | F5: 0.33470905 | G5: 0.33386769 | H5: 0
A6: province_4way | B6: Multi-Class Classification: Four Provinces | C6: knn_k7 | D6: k-NN (k=7) | E6: province_4way - knn_k7 | F6: 0.34742544 | G6: 0.34323768 | H6: 0
A7: province_4way | B7: Multi-Class Classification: Four Provinces | C7: knn_k11 | D7: k-NN (k=11) | E7: province_4way - knn_k11 | F7: 0.34764288 | G7: 0.34191197 | H7: 0
A8: province_4way | B8: Multi-Class Classification: Four Provinces | C8: nb | D8: Naive Bayes | E8: province_4way - nb | F8: 0.34908771 | G8: 0.34720647 | H8: 0
A9: province_4way | B9: Multi-Class Classification: Four Provinces | C9: rf | D9: Random Forest | E9: province_4way - rf | F9: 0.37670411 | G9: 0.33680229 | H9: 0
A10: province_4way | B10: Multi-Class Classification: Four Provinces | C10: svm_rbf | D10: SVM (RBF Kernel) | E10: province_4way - svm_rbf | F10: 0.37869702 | G10: 0.30716597 | H10: 0
A11: province_4way | B11: Multi-Class Classification: Four Provinces | C11: logreg_weighted | D11: Logistic Regression (Weighted) | E11: province_4way - logreg_weighted | F11: 0.39085497 | G11: 0.39014359 | H11: 0
A12: province_4way | B12: Multi-Class Classification: Four Provinces | C12: logreg | D12: Logistic Regression | E12: province_4way - logreg | F12: 0.39382908 | G12: 0.38317943 | H12: 0
A13: province_4way | B13: Multi-Class Classification: Four Provinces | C13: svm_linear | D13: SVM (Linear) | E13: province_4way - svm_linear | F13: 0.39387691 | G13: 0.38084229 | H13: 0
F14: =AVERAGE(F3:F13) -> 0.3611755 | G14: =AVERAGE(G3:G13) -> 0.34777038

Sheet Chart 1 - dail_vs_ni
A1: task_name | B1: task_name_better | C1: model_name | D1: model_name_better | E1: task_model | F1: balanced_accuracy_mean | G1: macro_f1_mean | H1: signal_flag
A2: =A1 -> task_name | B2: Binary Classification: Dáil vs Northern Ireland | C2: Random | D2: Random Baseline | E2: =_xlfn.CONCAT(A2, " - ",C2) -> task_name - Random | F2: 0.5 | G2: 0.5 | H2: 1
A3: dail_vs_ni | B3: Binary Classification: Dáil vs Northern Ireland | C3: knn_k11 | D3: k-NN (k=11) | E3: dail_vs_ni - knn_k11 | F3: 0.6569374 | G3: 0.68208074 | H3: 0
A4: dail_vs_ni | B4: Binary Classification: Dáil vs Northern Ireland | C4: svm_rbf | D4: SVM (RBF Kernel) | E4: dail_vs_ni - svm_rbf | F4: 0.65831235 | G4: 0.68346967 | H4: 0
A5: dail_vs_ni | B5: Binary Classification: Dáil vs Northern Ireland | C5: knn_k7 | D5: k-NN (k=7) | E5: dail_vs_ni - knn_k7 | F5: 0.65838804 | G5: 0.68349565 | H5: 0
A6: dail_vs_ni | B6: Binary Classification: Dáil vs Northern Ireland | C6: knn_k1 | D6: k-NN (k=1) | E6: dail_vs_ni - knn_k1 | F6: 0.66043167 | G6: 0.68279464 | H6: 0
A7: dail_vs_ni | B7: Binary Classification: Dáil vs Northern Ireland | C7: knn_k3 | D7: k-NN (k=3) | E7: dail_vs_ni - knn_k3 | F7: 0.66883771 | G7: 0.69531877 | H7: 0
A8: dail_vs_ni | B8: Binary Classification: Dáil vs Northern Ireland | C8: knn_k5 | D8: k-NN (k=5) | E8: dail_vs_ni - knn_k5 | F8: 0.67095073 | G8: 0.6977748 | H8: 0
A9: dail_vs_ni | B9: Binary Classification: Dáil vs Northern Ireland | C9: rf | D9: Random Forest | E9: dail_vs_ni - rf | F9: 0.7170707 | G9: 0.74418657 | H9: 0
A10: dail_vs_ni | B10: Binary Classification: Dáil vs Northern Ireland | C10: logreg | D10: Logistic Regression | E10: dail_vs_ni - logreg | F10: 0.72374581 | G10: 0.73700339 | H10: 0
A11: dail_vs_ni | B11: Binary Classification: Dáil vs Northern Ireland | C11: svm_linear | D11: SVM (Linear) | E11: dail_vs_ni - svm_linear | F11: 0.73857219 | G11: 0.75266747 | H11: 0
A12: dail_vs_ni | B12: Binary Classification: Dáil vs Northern Ireland | C12: logreg_weighted | D12: Logistic Regression (Weighted) | E12: dail_vs_ni - logreg_weighted | F12: 0.76545029 | G12: 0.74922279 | H12: 0
A13: dail_vs_ni | B13: Binary Classification: Dáil vs Northern Ireland | C13: nb | D13: Naive Bayes | E13: dail_vs_ni - nb | F13: 0.78742268 | G13: 0.79550003 | H13: 0
F14: =AVERAGE(F3:F13) -> 0.70055633 | G14: =AVERAGE(G3:G13) -> 0.71850132

Sheet Chart 1 - ulster_leinster_rest
A1: task_name | B1: task_name_better | C1: model_name | D1: model_name_better | E1: task_model | F1: balanced_accuracy_mean | G1: macro_f1_mean | H1: signal_flag
A2: =A1 -> task_name | B2: Multi-Class Classification: Ulster, Leinster, and Rest | C2: Random | D2: Random Baseline | E2: =_xlfn.CONCAT(A2, " - ",C2) -> task_name - Random | F2: 0.3333 | G2: 0.3333 | H2: 1
A3: ulster_leinster_rest | B3: Multi-Class Classification: Ulster, Leinster, and Rest | C3: knn_k1 | D3: k-NN (k=1) | E3: ulster_leinster_rest - knn_k1 | F3: 0.42159731 | G3: 0.42526366 | H3: 0
A4: ulster_leinster_rest | B4: Multi-Class Classification: Ulster, Leinster, and Rest | C4: knn_k5 | D4: k-NN (k=5) | E4: ulster_leinster_rest - knn_k5 | F4: 0.44101663 | G4: 0.44761157 | H4: 0
A5: ulster_leinster_rest | B5: Multi-Class Classification: Ulster, Leinster, and Rest | C5: knn_k3 | D5: k-NN (k=3) | E5: ulster_leinster_rest - knn_k3 | F5: 0.44857915 | G5: 0.45044054 | H5: 0
A6: ulster_leinster_rest | B6: Multi-Class Classification: Ulster, Leinster, and Rest | C6: knn_k7 | D6: k-NN (k=7) | E6: ulster_leinster_rest - knn_k7 | F6: 0.4569684 | G6: 0.46326218 | H6: 0
A7: ulster_leinster_rest | B7: Multi-Class Classification: Ulster, Leinster, and Rest | C7: knn_k11 | D7: k-NN (k=11) | E7: ulster_leinster_rest - knn_k11 | F7: 0.45859313 | G7: 0.46739832 | H7: 0
A8: ulster_leinster_rest | B8: Multi-Class Classification: Ulster, Leinster, and Rest | C8: nb | D8: Naive Bayes | E8: ulster_leinster_rest - nb | F8: 0.47583234 | G8: 0.48175538 | H8: 0
A9: ulster_leinster_rest | B9: Multi-Class Classification: Ulster, Leinster, and Rest | C9: rf | D9: Random Forest | E9: ulster_leinster_rest - rf | F9: 0.49953826 | G9: 0.50641569 | H9: 0
A10: ulster_leinster_rest | B10: Multi-Class Classification: Ulster, Leinster, and Rest | C10: logreg_weighted | D10: Logistic Regression (Weighted) | E10: ulster_leinster_rest - logreg_weighted | F10: 0.50391033 | G10: 0.49358594 | H10: 0
A11: ulster_leinster_rest | B11: Multi-Class Classification: Ulster, Leinster, and Rest | C11: logreg | D11: Logistic Regression | E11: ulster_leinster_rest - logreg | F11: 0.50573616 | G11: 0.50061384 | H11: 0
A12: ulster_leinster_rest | B12: Multi-Class Classification: Ulster, Leinster, and Rest | C12: svm_linear | D12: SVM (Linear) | E12: ulster_leinster_rest - svm_linear | F12: 0.5143612 | G12: 0.51081081 | H12: 0
A13: ulster_leinster_rest | B13: Multi-Class Classification: Ulster, Leinster, and Rest | C13: svm_rbf | D13: SVM (RBF Kernel) | E13: ulster_leinster_rest - svm_rbf | F13: 0.5240897 | G13: 0.51867426 | H13: 0
F14: =AVERAGE(F3:F13) -> 0.47729296 | G14: =AVERAGE(G3:G13) -> 0.47871202

Sheet Chart 1 - leinster_vs_rest
A1: task_name | B1: task_name_better | C1: model_name | D1: model_name_better | E1: task_model | F1: balanced_accuracy_mean | G1: macro_f1_mean | H1: signal_flag
A2: =A1 -> task_name | B2: Binary Classification: Leinster vs Rest | C2: Random | D2: Random Baseline | E2: =_xlfn.CONCAT(A2, " - ",C2) -> task_name - Random | F2: 0.5 | G2: 0.5 | H2: 1
A3: leinster_vs_rest | B3: Binary Classification: Leinster vs Rest | C3: svm_rbf | D3: SVM (RBF Kernel) | E3: leinster_vs_rest - svm_rbf | F3: 0.5 | G3: 0.41270394 | H3: 0
A4: leinster_vs_rest | B4: Binary Classification: Leinster vs Rest | C4: rf | D4: Random Forest | E4: leinster_vs_rest - rf | F4: 0.521325 | G4: 0.51289203 | H4: 0
A5: leinster_vs_rest | B5: Binary Classification: Leinster vs Rest | C5: knn_k1 | D5: k-NN (k=1) | E5: leinster_vs_rest - knn_k1 | F5: 0.54934217 | G5: 0.54146896 | H5: 0
A6: leinster_vs_rest | B6: Binary Classification: Leinster vs Rest | C6: svm_linear | D6: SVM (Linear) | E6: leinster_vs_rest - svm_linear | F6: 0.55479136 | G6: 0.5594403 | H6: 0
A7: leinster_vs_rest | B7: Binary Classification: Leinster vs Rest | C7: knn_k3 | D7: k-NN (k=3) | E7: leinster_vs_rest - knn_k3 | F7: 0.55833869 | G7: 0.55399819 | H7: 0
A8: leinster_vs_rest | B8: Binary Classification: Leinster vs Rest | C8: logreg | D8: Logistic Regression | E8: leinster_vs_rest - logreg | F8: 0.55836683 | G8: 0.56276213 | H8: 0
A9: leinster_vs_rest | B9: Binary Classification: Leinster vs Rest | C9: knn_k5 | D9: k-NN (k=5) | E9: leinster_vs_rest - knn_k5 | F9: 0.56140122 | G9: 0.56025326 | H9: 0
A10: leinster_vs_rest | B10: Binary Classification: Leinster vs Rest | C10: knn_k11 | D10: k-NN (k=11) | E10: leinster_vs_rest - knn_k11 | F10: 0.57259216 | G10: 0.57526025 | H10: 0
A11: leinster_vs_rest | B11: Binary Classification: Leinster vs Rest | C11: knn_k7 | D11: k-NN (k=7) | E11: leinster_vs_rest - knn_k7 | F11: 0.57621 | G11: 0.57708392 | H11: 0
A12: leinster_vs_rest | B12: Binary Classification: Leinster vs Rest | C12: nb | D12: Naive Bayes | E12: leinster_vs_rest - nb | F12: 0.60023141 | G12: 0.55454494 | H12: 0
A13: leinster_vs_rest | B13: Binary Classification: Leinster vs Rest | C13: logreg_weighted | D13: Logistic Regression (Weighted) | E13: leinster_vs_rest - logreg_weighted | F13: 0.61577722 | G13: 0.58346027 | H13: 0
F14: =AVERAGE(F3:F13) -> 0.56076146 | G14: =AVERAGE(G3:G13) -> 0.54489711

Sheet Chart 1 - ulster_vs_rest
A1: task_name | B1: task_name_better | C1: model_name | D1: model_name_better | E1: task_model | F1: balanced_accuracy_mean | G1: macro_f1_mean | H1: signal_flag
A2: =A1 -> task_name | B2: Binary Classification: Ulster vs Rest | C2: Random | D2: Random Baseline | E2: =_xlfn.CONCAT(A2, " - ",C2) -> task_name - Random | F2: 0.5 | G2: 0.5 | H2: 1
A3: ulster_vs_rest | B3: Binary Classification: Ulster vs Rest | C3: knn_k1 | D3: k-NN (k=1) | E3: ulster_vs_rest - knn_k1 | F3: 0.63313511 | G3: 0.63990942 | H3: 0
A4: ulster_vs_rest | B4: Binary Classification: Ulster vs Rest | C4: knn_k3 | D4: k-NN (k=3) | E4: ulster_vs_rest - knn_k3 | F4: 0.6400638 | G4: 0.64719294 | H4: 0
A5: ulster_vs_rest | B5: Binary Classification: Ulster vs Rest | C5: knn_k5 | D5: k-NN (k=5) | E5: ulster_vs_rest - knn_k5 | F5: 0.64803506 | G5: 0.65663799 | H5: 0
A6: ulster_vs_rest | B6: Binary Classification: Ulster vs Rest | C6: knn_k11 | D6: k-NN (k=11) | E6: ulster_vs_rest - knn_k11 | F6: 0.65776007 | G6: 0.66833037 | H6: 0
A7: ulster_vs_rest | B7: Binary Classification: Ulster vs Rest | C7: knn_k7 | D7: k-NN (k=7) | E7: ulster_vs_rest - knn_k7 | F7: 0.6646431 | G7: 0.67586051 | H7: 0
A8: ulster_vs_rest | B8: Binary Classification: Ulster vs Rest | C8: svm_rbf | D8: SVM (RBF Kernel) | E8: ulster_vs_rest - svm_rbf | F8: 0.69674609 | G8: 0.70886431 | H8: 0
A9: ulster_vs_rest | B9: Binary Classification: Ulster vs Rest | C9: rf | D9: Random Forest | E9: ulster_vs_rest - rf | F9: 0.71604613 | G9: 0.73153082 | H9: 0
A10: ulster_vs_rest | B10: Binary Classification: Ulster vs Rest | C10: nb | D10: Naive Bayes | E10: ulster_vs_rest - nb | F10: 0.72348344 | G10: 0.73490381 | H10: 0
A11: ulster_vs_rest | B11: Binary Classification: Ulster vs Rest | C11: logreg | D11: Logistic Regression | E11: ulster_vs_rest - logreg | F11: 0.72519682 | G11: 0.73156943 | H11: 0
A12: ulster_vs_rest | B12: Binary Classification: Ulster vs Rest | C12: svm_linear | D12: SVM (Linear) | E12: ulster_vs_rest - svm_linear | F12: 0.73493248 | G12: 0.74274351 | H12: 0
A13: ulster_vs_rest | B13: Binary Classification: Ulster vs Rest | C13: logreg_weighted | D13: Logistic Regression (Weighted) | E13: ulster_vs_rest - logreg_weighted | F13: 0.74775797 | G13: 0.74442445 | H13: 0
F14: =AVERAGE(F3:F13) -> 0.68980001 | G14: =AVERAGE(G3:G13) -> 0.69836069

Sheet Chart 2 - BestModelPerTask
A1: task_name | B1: task_name_better | C1: model_name | D1: model_name_better | E1: task_model | F1: task_model_better | G1: balanced_accuracy_mean | H1: macro_f1_mean | I1: Random Baseline | J1: RelativeImprovementOverBaseline
A2: dail_only_province | B2: Dáil Speakers | C2: logreg | D2: Logistic Regression | E2: dail_only_province - logreg | F2: =Table16[[#This Row],[task_name_better]] & CHAR(10) & Table16[[#This Row],[model_name_better]] -> Dáil Speakers Logistic Regression | G2: 0.27210887 | H2: 0.25396345 | I2: 0.25 | J2: =(Table16[[#This Row],[balanced_accuracy_mean]]-Table16[[#This Row],[Random Baseline]]) / Table16[[#This Row],[Random Baseline]] -> 0.088435469
A3: province_4way | B3: Four Provinces | C3: svm_linear | D3: SVM (Linear) | E3: province_4way - svm_linear | F3: =Table16[[#This Row],[task_name_better]] & CHAR(10) & Table16[[#This Row],[model_name_better]] -> Four Provinces SVM (Linear) | G3: 0.39387691 | H3: 0.38084229 | I3: 0.25 | J3: =(Table16[[#This Row],[balanced_accuracy_mean]]-Table16[[#This Row],[Random Baseline]]) / Table16[[#This Row],[Random Baseline]] -> 0.57550764
A4: ulster_leinster_rest | B4: Ulster, Leinster, and Rest | C4: svm_rbf | D4: SVM (RBF Kernel) | E4: ulster_leinster_rest - svm_rbf | F4: =Table16[[#This Row],[task_name_better]] & CHAR(10) & Table16[[#This Row],[model_name_better]] -> Ulster, Leinster, and Rest SVM (RBF Kernel) | G4: 0.5240897 | H4: 0.51867426 | I4: 0.3333 | J4: =(Table16[[#This Row],[balanced_accuracy_mean]]-Table16[[#This Row],[Random Baseline]]) / Table16[[#This Row],[Random Baseline]] -> 0.57242634
A5: leinster_vs_rest | B5: Leinster vs Rest | C5: logreg_weighted | D5: Logistic Regression (Weighted) | E5: leinster_vs_rest - logreg_weighted | F5: =Table16[[#This Row],[task_name_better]] & CHAR(10) & Table16[[#This Row],[model_name_better]] -> Leinster vs Rest Logistic Regression (Weighted) | G5: 0.6158 | H5: 0.5835 | I5: 0.5 | J5: =(Table16[[#This Row],[balanced_accuracy_mean]]-Table16[[#This Row],[Random Baseline]]) / Table16[[#This Row],[Random Baseline]] -> 0.2316
A6: ulster_vs_rest | B6: Ulster vs Rest | C6: logreg_weighted | D6: Logistic Regression (Weighted) | E6: ulster_vs_rest - logreg_weighted | F6: =Table16[[#This Row],[task_name_better]] & CHAR(10) & Table16[[#This Row],[model_name_better]] -> Ulster vs Rest Logistic Regression (Weighted) | G6: 0.74775797 | H6: 0.74442445 | I6: 0.5 | J6: =(Table16[[#This Row],[balanced_accuracy_mean]]-Table16[[#This Row],[Random Baseline]]) / Table16[[#This Row],[Random Baseline]] -> 0.49551593
A7: dail_vs_ni | B7: Dáil vs Northern Ireland | C7: nb | D7: Naive Bayes | E7: dail_vs_ni - nb | F7: =Table16[[#This Row],[task_name_better]] & CHAR(10) & Table16[[#This Row],[model_name_better]] -> Dáil vs Northern Ireland Naive Bayes | G7: 0.78742268 | H7: 0.79550003 | I7: 0.5 | J7: =(Table16[[#This Row],[balanced_accuracy_mean]]-Table16[[#This Row],[Random Baseline]]) / Table16[[#This Row],[Random Baseline]] -> 0.57484536

Sheet Chart 3 - AverageAccuracyTask
A1: task_name | B1: avg_accuracy
A2: Province (Dáil Speakers) | B2: =AVERAGE('Chart 1 - dail_only_province'!F3:F13) -> 0.26067879
A3: Four Provinces | B3: =AVERAGE('Chart 1 - province_4way'!F3:F13) -> 0.3611755
A4: Ulster / Leinster / Rest | B4: =AVERAGE('Chart 1 - ulster_leinster_rest'!F3:F13) -> 0.47729296
A5: Leinster vs Rest | B5: =AVERAGE('Chart 1 - leinster_vs_rest'!F3:F13) -> 0.56076146
A6: Ulster vs Rest | B6: =AVERAGE('Chart 1 - ulster_vs_rest'!F3:F13) -> 0.68980001
A7: Dáil vs Northern Ireland | B7: =AVERAGE('Chart 1 - dail_vs_ni'!F3:F13) -> 0.70055633

Sheet Chart4 - relativeAccuracyModel
A1: task_name | B1: model_name | C1: task_model | D1: balanced_accuracy_mean | F1: model_name | G1: model_name_better | H1: avg_relative_improvement
A2: dail_only_province | B2: knn_k1 | C2: dail_only_province - knn_k1 | D2: 0.26418718 | F2: knn_k1 | G2: k-NN (k=1) | H2: =AVERAGEIF(irish_model_summary_rebuilt!B:B, F2, irish_model_summary_rebuilt!N:N) -> 0.22058773
A3: dail_vs_ni | B3: knn_k1 | C3: dail_vs_ni - knn_k1 | D3: 0.66043167 | F3: knn_k3 | G3: k-NN (k=3) | H3: =AVERAGEIF(irish_model_summary_rebuilt!B:B, F3, irish_model_summary_rebuilt!N:N) -> 0.24318918
A4: leinster_vs_rest | B4: knn_k1 | C4: leinster_vs_rest - knn_k1 | D4: 0.54934217 | F4: knn_k5 | G4: k-NN (k=5) | H4: =AVERAGEIF(irish_model_summary_rebuilt!B:B, F4, irish_model_summary_rebuilt!N:N) -> 0.24736138
A5: province_4way | B5: knn_k1 | C5: province_4way - knn_k1 | D5: 0.32904197 | F5: knn_k7 | G5: k-NN (k=7) | H5: =AVERAGEIF(irish_model_summary_rebuilt!B:B, F5, irish_model_summary_rebuilt!N:N) -> 0.26890001
A6: ulster_leinster_rest | B6: knn_k1 | C6: ulster_leinster_rest - knn_k1 | D6: 0.42159731 | F6: knn_k11 | G6: k-NN (k=11) | H6: =AVERAGEIF(irish_model_summary_rebuilt!B:B, F6, irish_model_summary_rebuilt!N:N) -> 0.27021458
A7: ulster_vs_rest | B7: knn_k1 | C7: ulster_vs_rest - knn_k1 | D7: 0.63313511 | F7: svm_rbf | G7: SVM (RBF Kernel) | H7: =AVERAGEIF(irish_model_summary_rebuilt!B:B, F7, irish_model_summary_rebuilt!N:N) -> 0.29743822
A8: dail_only_province | B8: knn_k3 | C8: dail_only_province - knn_k3 | D8: 0.2636679 | F8: rf | G8: Random Forest | H8: =AVERAGEIF(irish_model_summary_rebuilt!B:B, F8, irish_model_summary_rebuilt!N:N) -> 0.3173739
A9: dail_vs_ni | B9: knn_k3 | C9: dail_vs_ni - knn_k3 | D9: 0.66883771 | F9: nb | G9: Naive Bayes | H9: =AVERAGEIF(irish_model_summary_rebuilt!B:B, F9, irish_model_summary_rebuilt!N:N) -> 0.33499851
A10: leinster_vs_rest | B10: knn_k3 | C10: leinster_vs_rest - knn_k3 | D10: 0.55833869 | F10: logreg | G10: Logistic Regression | H10: =AVERAGEIF(irish_model_summary_rebuilt!B:B, F10, irish_model_summary_rebuilt!N:N) -> 0.36592987
A11: province_4way | B11: knn_k3 | C11: province_4way - knn_k3 | D11: 0.33106141 | F11: svm_linear | G11: SVM (Linear) | H11: =AVERAGEIF(irish_model_summary_rebuilt!B:B, F11, irish_model_summary_rebuilt!N:N) -> 0.37003462
A12: ulster_leinster_rest | B12: knn_k3 | C12: ulster_leinster_rest - knn_k3 | D12: 0.44857915 | F12: logreg_weighted | G12: Logistic Regression (Weighted) | H12: =AVERAGEIF(irish_model_summary_rebuilt!B:B, F12, irish_model_summary_rebuilt!N:N) -> 0.40344671
A13: ulster_vs_rest | B13: knn_k3 | C13: ulster_vs_rest - knn_k3 | D13: 0.6400638
A14: dail_only_province | B14: knn_k5 | C14: dail_only_province - knn_k5 | D14: 0.26537703
A15: dail_vs_ni | B15: knn_k5 | C15: dail_vs_ni - knn_k5 | D15: 0.67095073
A16: leinster_vs_rest | B16: knn_k5 | C16: leinster_vs_rest - knn_k5 | D16: 0.56140122
A17: province_4way | B17: knn_k5 | C17: province_4way - knn_k5 | D17: 0.33470905
A18: ulster_leinster_rest | B18: knn_k5 | C18: ulster_leinster_rest - knn_k5 | D18: 0.44101663
A19: ulster_vs_rest | B19: knn_k5 | C19: ulster_vs_rest - knn_k5 | D19: 0.64803506
A20: dail_only_province | B20: knn_k7 | C20: dail_only_province - knn_k7 | D20: 0.26357771
A21: dail_vs_ni | B21: knn_k7 | C21: dail_vs_ni - knn_k7 | D21: 0.65838804
A22: leinster_vs_rest | B22: knn_k7 | C22: leinster_vs_rest - knn_k7 | D22: 0.57621
A23: province_4way | B23: knn_k7 | C23: province_4way - knn_k7 | D23: 0.34742544
A24: ulster_leinster_rest | B24: knn_k7 | C24: ulster_leinster_rest - knn_k7 | D24: 0.4569684
... A67: ulster_vs_rest | B67: knn_k11 | C67: ulster_vs_rest - knn_k11 | D67: 0.65776007
